Workbook

Sheet Sales Data
A1: Order ID | B1: Date | C1: Region | D1: Salesperson | E1: Product | F1: Category | G1: Units Sold | H1: Unit Price | I1: Discount | J1: Customer Type | K1: Total Sale | L1: Discount Amount | M1: Order Size | N1: High Value | O1: Revenue per Unit
A2: 1001 | B2: 45985 | C2: South | D2: Bilal Ahmed | E2: Wireless Mouse | F2: Electronics | G2: 18 | H2: 23.1 | I2: 0 | J2: Online | K2: =G2*H2*(1-I2) -> 415.8 | L2: =G2*H2*I2 -> 0 | M2: =IF(G2<10,"Small",IF(G2<=25,"Medium","Large")) -> Medium | N2: =IF(AND(K2>2000,J2="Wholesale"),"Yes","No") -> No | O2: =IFERROR(K2/G2,"N/A") -> 23.1
A3: 1002 | B3: 45710 | C3: North | D3: Sana Khan | E3: Webcam | F3: Electronics | G3: 28 | H3: 56.03 | I3: 0 | J3: Retail | K3: =G3*H3*(1-I3) -> 1568.84 | L3: =G3*H3*I3 -> 0 | M3: =IF(G3<10,"Small",IF(G3<=25,"Medium","Large")) -> Large | N3: =IF(AND(K3>2000,J3="Wholesale"),"Yes","No") -> No | O3: =IFERROR(K3/G3,"N/A") -> 56.03
A4: 1003 | B4: 45777 | C4: Central | D4: Zainab Iqbal | E4: Webcam | F4: Electronics | G4: 36 | H4: 60.98 | I4: 0 | J4: Retail | K4: =G4*H4*(1-I4) -> 2195.28 | L4: =G4*H4*I4 -> 0 | M4: =IF(G4<10,"Small",IF(G4<=25,"Medium","Large")) -> Large | N4: =IF(AND(K4>2000,J4="Wholesale"),"Yes","No") -> No | O4: =IFERROR(K4/G4,"N/A") -> 60.98
A5: 1004 | B5: 45887 | C5: West | D5: Hina Farooq | E5: Desk Lamp | F5: Furniture | G5: 1 | H5: 33.76 | I5: 0 | J5: Wholesale | K5: =G5*H5*(1-I5) -> 33.76 | L5: =G5*H5*I5 -> 0 | M5: =IF(G5<10,"Small",IF(G5<=25,"Medium","Large")) -> Small | N5: =IF(AND(K5>2000,J5="Wholesale"),"Yes","No") -> No | O5: =IFERROR(K5/G5,"N/A") -> 33.76
A6: 1005 | B6: 45737 | C6: North | D6: Zainab Iqbal | E6: Standing Desk | F6: Furniture | G6: 22 | H6: 450.72 | I6: 0 | J6: Retail | K6: =G6*H6*(1-I6) -> 9915.84 | L6: =G6*H6*I6 -> 0 | M6: =IF(G6<10,"Small",IF(G6<=25,"Medium","Large")) -> Medium | N6: =IF(AND(K6>2000,J6="Wholesale"),"Yes","No") -> No | O6: =IFERROR(K6/G6,"N/A") -> 450.72
A7: 1006 | B7: 45841 | C7: West | D7: Sana Khan | E7: Notebook Pack | F7: Stationery | G7: 3 | H7: 8.13 | I7: 0.15 | J7: Wholesale | K7: =G7*H7*(1-I7) -> 20.7315 | L7: =G7*H7*I7 -> 3.6585 | M7: =IF(G7<10,"Small",IF(G7<=25,"Medium","Large")) -> Small | N7: =IF(AND(K7>2000,J7="Wholesale"),"Yes","No") -> No | O7: =IFERROR(K7/G7,"N/A") -> 6.9105
A8: 1007 | B8: 45698 | C8: Central | D8: Ayesha Malik | E8: Webcam | F8: Electronics | G8: 40 | H8: 58.01 | I8: 0 | J8: Online | K8: =G8*H8*(1-I8) -> 2320.4 | L8: =G8*H8*I8 -> 0 | M8: =IF(G8<10,"Small",IF(G8<=25,"Medium","Large")) -> Large | N8: =IF(AND(K8>2000,J8="Wholesale"),"Yes","No") -> No | O8: =IFERROR(K8/G8,"N/A") -> 58.01
A9: 1008 | B9: 45693 | C9: South | D9: Sana Khan | E9: Laptop | F9: Electronics | G9: 19 | H9: 871.93 | I9: 0 | J9: Wholesale | K9: =G9*H9*(1-I9) -> 16566.67 | L9: =G9*H9*I9 -> 0 | M9: =IF(G9<10,"Small",IF(G9<=25,"Medium","Large")) -> Medium | N9: =IF(AND(K9>2000,J9="Wholesale"),"Yes","No") -> Yes | O9: =IFERROR(K9/G9,"N/A") -> 871.93
A10: 1009 | B10: 45800 | C10: East | D10: Hina Farooq | E10: Filing Cabinet | F10: Furniture | G10: 24 | H10: 153.26 | I10: 0 | J10: Retail | K10: =G10*H10*(1-I10) -> 3678.24 | L10: =G10*H10*I10 -> 0 | M10: =IF(G10<10,"Small",IF(G10<=25,"Medium","Large")) -> Medium | N10: =IF(AND(K10>2000,J10="Wholesale"),"Yes","No") -> No | O10: =IFERROR(K10/G10,"N/A") -> 153.26
A11: 1010 | B11: 46001 | C11: South | D11: Ayesha Malik | E11: Monitor | F11: Electronics | G11: 5 | H11: 227.1 | I11: 0.1 | J11: Retail | K11: =G11*H11*(1-I11) -> 1021.95 | L11: =G11*H11*I11 -> 113.55 | M11: =IF(G11<10,"Small",IF(G11<=25,"Medium","Large")) -> Small | N11: =IF(AND(K11>2000,J11="Wholesale"),"Yes","No") -> No | O11: =IFERROR(K11/G11,"N/A") -> 204.39
A12: 1011 | B12: 45894 | C12: East | D12: Ali Raza | E12: Pen Set | F12: Stationery | G12: 36 | H12: 11.56 | I12: 0 | J12: Retail | K12: =G12*H12*(1-I12) -> 416.16 | L12: =G12*H12*I12 -> 0 | M12: =IF(G12<10,"Small",IF(G12<=25,"Medium","Large")) -> Large | N12: =IF(AND(K12>2000,J12="Wholesale"),"Yes","No") -> No | O12: =IFERROR(K12/G12,"N/A") -> 11.56
A13: 1012 | B13: 45674 | C13: Central | D13: Hina Farooq | E13: Notebook Pack | F13: Stationery | G13: 5 | H13: 7.87 | I13: 0 | J13: Retail | K13: =G13*H13*(1-I13) -> 39.35 | L13: =G13*H13*I13 -> 0 | M13: =IF(G13<10,"Small",IF(G13<=25,"Medium","Large")) -> Small | N13: =IF(AND(K13>2000,J13="Wholesale"),"Yes","No") -> No | O13: =IFERROR(K13/G13,"N/A") -> 7.87
... A201: 1200 | B201: 46005 | C201: East | D201: Sana Khan | E201: Desk Lamp | F201: Furniture | G201: 22 | H201: 32.49 | I201: 0 | J201: Online | K201: =G201*H201*(1-I201) -> 714.78 | L201: =G201*H201*I201 -> 0 | M201: =IF(G201<10,"Small",IF(G201<=25,"Medium","Large")) -> Medium | N201: =IF(AND(K201>2000,J201="Wholesale"),"Yes","No") -> No | O201: =IFERROR(K201/G201,"N/A") -> 32.49

Sheet Practice Questions
A1: Excel Practice Questions — exact cells to use
A2: Data is on 'Sales Data' (rows 2-201). Answers/formulas go in the yellow cells on 'Sales Data' (columns K-O) or on 'Workspace'. Type formulas yourself — the cell references below tell you exactly where.
A4: Part 1: Basic Formulas
A5: 1. | B5: 'Sales Data'!K2 → calculate Total Sale = Units Sold x Unit Price x (1 - Discount). Copy down to K201.
A6: 2. | B6: 'Sales Data'!L2 → calculate Discount Amount = Units Sold x Unit Price x Discount. Copy down to L201.
A7: 3. | B7: 'Workspace'!B4 → Total Revenue: sum all of 'Sales Data'!K2:K201.
A8: 4. | B8: 'Workspace'!B5 → Average Unit Price: average of 'Sales Data'!H2:H201.
A9: 5. | B9: 'Workspace'!B6 → Minimum Unit Price: minimum of 'Sales Data'!H2:H201.
A10: 6. | B10: 'Workspace'!B7 → Maximum Unit Price: maximum of 'Sales Data'!H2:H201.
A11: 7. | B11: 'Workspace'!B8 → Total Number of Orders: count the entries in 'Sales Data'!A2:A201.
A13: Part 2: Logical Functions (IF, AND, OR, nested IF, IFERROR)
A14: 1. | B14: 'Sales Data'!M2 → Order Size: nested IF using 'Sales Data'!G2 (Units Sold) — 'Small' if under 10, 'Medium' if 10-25, 'Large' if over 25. Copy down to M201.
A15: 2. | B15: 'Sales Data'!N2 → High Value: 'Yes' if K2 (Total Sale) is over 2000 AND J2 (Customer Type) is 'Wholesale', otherwise 'No'. Use IF + AND. Copy down to N201.
A16: 3. | B16: 'Sales Data'!O2 → Revenue per Unit: K2 divided by G2, wrapped in IFERROR so it shows 'N/A' instead of an error if G2 is 0 or blank. Copy down to O201.
A18: Part 3: Lookup Functions (VLOOKUP / INDEX-MATCH)
A19: 1. | B19: 'Workspace'!A12:B21 → list the 10 unique Products with their Category (check 'Sales Data' columns E and F to find each pair — there are exactly 10 distinct products).
A20: 2. | B20: 'Workspace'!B23 → type any product name exactly as it appears in your table above.
A21: 3. | B21: 'Workspace'!B24 → use VLOOKUP to look up B23 in 'Workspace'!A12:B21 and return the Category (column 2, exact match).
A22: 4. | B22: 'Workspace'!B25 → use INDEX + MATCH to find the Salesperson ('Sales Data'!D2:D201) on the row where Total Sale ('Sales Data'!K2:K201) is at its maximum.
A24: Part 4: Conditional Aggregation (SUMIF/SUMIFS, COUNTIF, AVERAGEIF)
A25: 1. | B25: 'Workspace'!B28 → SUMIF: total 'Sales Data'!K2:K201 where 'Sales Data'!C2:C201 (Region) equals 'North'.
A26: 2. | B26: 'Workspace'!B29 → SUMIFS: total 'Sales Data'!K2:K201 where Category ('Sales Data'!F2:F201) is 'Electronics' AND Salesperson ('Sales Data'!D2:D201) is 'Ali Raza'.
A27: 3. | B27: 'Workspace'!B31:B38 → COUNTIF: for each Salesperson listed in A31:A38, count their matching orders in 'Sales Data'!D2:D201.
A28: 4. | B28: 'Workspace'!B40 → AVERAGEIF: average 'Sales Data'!H2:H201 (Unit Price) where 'Sales Data'!J2:J201 (Customer Type) is 'Online'.
A30: Part 5: Pivot Tables
A31: 1. | B31: Click any cell inside 'Sales Data'!A1:O201, then Insert > PivotTable > New Worksheet. Drag Region into Rows and Total Sale into Values (set to Sum) to get Total Revenue by Region.
A32: 2. | B32: In that same pivot, drag Category into Rows underneath Region to break each region's total down by category.
A33: 3. | B33: Build a second pivot with Salesperson in Rows and Total Sale in Values, then Insert > PivotChart > Clustered Column to visualize revenue by salesperson.
A34: 4. | B34: Drag Customer Type into the Filters area of either pivot and filter it to 'Wholesale' — watch the totals update.
A36: Part 6: Conditional Formatting
A37: 1. | B37: Select 'Sales Data'!K2:K201 → Home > Conditional Formatting > Highlight Cells Rules > Greater Than > 3000 → Green Fill.
A38: 2. | B38: Select 'Sales Data'!H2:H201 → Conditional Formatting > Color Scales > choose a 3-color scale (green-yellow-red).
A39: 3. | B39: Select 'Sales Data'!I2:I201 → Conditional Formatting > Icon Sets > 3 Traffic Lights, so discounts of 10% or more stand out.
A41: Part 7: Data Validation & Cleaning
A42: 1. | B42: 'Workspace'!B43 already has a dropdown list applied (North/South/East/West/Central) — click it, confirm the arrow shows, and test selecting each option.
A43: 2. | B43: In a spare cell (e.g. 'Sales Data'!Q2) type =TRIM('Sales Data'!D2) and copy down to Q201, then compare against column D to confirm there are no extra spaces.
A44: 3. | B44: Select 'Sales Data'!A2:A201 (Order ID) → Conditional Formatting > Highlight Cells Rules > Duplicate Values — confirm nothing highlights (no duplicate Order IDs).
A46: Part 8: Charts
A47: 1. | B47: Build a small summary table (e.g. in a spare area of 'Workspace') of each Product with total revenue using SUMIF, then select it and Insert > Column Chart.
A48: 2. | B48: In 'Sales Data'!P2 type =TEXT(B2,"mmm-yyyy") and copy down to P201 to get a Month label. Build a monthly totals table with SUMIF against column P, then Insert > Line Chart to show the revenue trend.
...

Sheet Workspace
A1: Workspace — enter your formulas/answers in the yellow cells
A3: Part 1: Basic Formulas
A4: Total Revenue (sum of Sales Data column K) | B4: =SUM('Sales Data'!K2:K201) -> 676403.73
A5: Average Unit Price (Sales Data column H) | B5: =AVERAGE('Sales Data'!H2:H201) -> 179.0945
A6: Minimum Unit Price | B6: =MIN('Sales Data'!H2:H201) -> 7.47
A7: Maximum Unit Price | B7: =MAX('Sales Data'!H2:H201) -> 910.69
A8: Total Number of Orders | B8: =COUNT('Sales Data'!A2:A201) -> 200
A10: Part 3: Lookup Table (fill Product + Category, 10 unique products)
A11: Product | B11: Category
A12: Laptop | B12: Electronics
A13: Wireless Mouse | B13: Electronics
A14: Office Chair | B14: Furniture
A15: Standing Desk | B15: Furniture
A16: Monitor | B16: Electronics
A17: Notebook Pack | B17: Stationery
A18: Pen Set | B18: Stationery
A19: Filing Cabinet | B19: Furniture
A20: Webcam | B20: Electronics
A21: Desk Lamp | B21: Furniture
A23: Type any product name here | B23: Laptop
A24: VLOOKUP result (Category, from table above) | B24: =VLOOKUP(B23,A12:B21,2,FALSE()) -> Electronics
A25: Salesperson with the single highest Total Sale (INDEX+MATCH) | B25: =INDEX('Sales Data'!D2:D201,MATCH(MAX('Sales Data'!K2:K201),'Sales Data'!K2:K201,0)) -> Hamza Sheikh
A27: Part 4: Conditional Aggregation
A28: Total Revenue — Region = North only (SUMIF) | B28: =SUMIF('Sales Data'!C2:C201,"North",'Sales Data'!K2:K201) -> 162152.87
A29: Total Revenue — Category=Electronics AND Salesperson=Ali Raza (SUMIFS) | B29: =SUMIFS('Sales Data'!K2:K201,'Sales Data'!F2:F201,"Electronics",'Sales Data'!D2:D201,"Ali Raza") -> 19722.083
A30: Salesperson | B30: Order Count
A31: Ali Raza | B31: =COUNTIF('Sales Data'!$D$2:$D$201,A31) -> 19
A32: Sana Khan | B32: =COUNTIF('Sales Data'!$D$2:$D$201,A32) -> 36
A33: Bilal Ahmed | B33: =COUNTIF('Sales Data'!$D$2:$D$201,A33) -> 26
A34: Ayesha Malik | B34: =COUNTIF('Sales Data'!$D$2:$D$201,A34) -> 27
A35: Usman Tariq | B35: =COUNTIF('Sales Data'!$D$2:$D$201,A35) -> 27
A36: Hina Farooq | B36: =COUNTIF('Sales Data'!$D$2:$D$201,A36) -> 18
A37: Zainab Iqbal | B37: =COUNTIF('Sales Data'!$D$2:$D$201,A37) -> 25
A38: Hamza Sheikh | B38: =COUNTIF('Sales Data'!$D$2:$D$201,A38) -> 22
A40: Average Unit Price — Customer Type = Online only (AVERAGEIF) | B40: =AVERAGEIF('Sales Data'!J2:J201,"Online",'Sales Data'!H2:H201) -> 174.25792
A42: Part 7: Data Validation test cell
A43: Region dropdown (apply Data Validation list here)

Sheet Pivot Summary
A1: Revenue by Region x Category (built with SUMIFS — recreate as a real PivotTable via Insert > PivotTable for practice)
A3: Region | B3: Electronics | C3: Furniture | D3: Stationery | E3: Total
A4: North | B4: =SUMIFS('Sales Data'!$K$2:$K$201,'Sales Data'!$C$2:$C$201,$A4,'Sales Data'!$F$2:$F$201,B$3) -> 91378.007 | C4: =SUMIFS('Sales Data'!$K$2:$K$201,'Sales Data'!$C$2:$C$201,$A4,'Sales Data'!$F$2:$F$201,C$3) -> 69253.69 | D4: =SUMIFS('Sales Data'!$K$2:$K$201,'Sales Data'!$C$2:$C$201,$A4,'Sales Data'!$F$2:$F$201,D$3) -> 1521.173 | E4: =SUM(B4:D4) -> 162152.87
A5: South | B5: =SUMIFS('Sales Data'!$K$2:$K$201,'Sales Data'!$C$2:$C$201,$A5,'Sales Data'!$F$2:$F$201,B$3) -> 47214.757 | C5: =SUMIFS('Sales Data'!$K$2:$K$201,'Sales Data'!$C$2:$C$201,$A5,'Sales Data'!$F$2:$F$201,C$3) -> 35793.993 | D5: =SUMIFS('Sales Data'!$K$2:$K$201,'Sales Data'!$C$2:$C$201,$A5,'Sales Data'!$F$2:$F$201,D$3) -> 1076.468 | E5: =SUM(B5:D5) -> 84085.218
A6: East | B6: =SUMIFS('Sales Data'!$K$2:$K$201,'Sales Data'!$C$2:$C$201,$A6,'Sales Data'!$F$2:$F$201,B$3) -> 85581.394 | C6: =SUMIFS('Sales Data'!$K$2:$K$201,'Sales Data'!$C$2:$C$201,$A6,'Sales Data'!$F$2:$F$201,C$3) -> 79186.833 | D6: =SUMIFS('Sales Data'!$K$2:$K$201,'Sales Data'!$C$2:$C$201,$A6,'Sales Data'!$F$2:$F$201,D$3) -> 2301.7915 | E6: =SUM(B6:D6) -> 167070.02
A7: West | B7: =SUMIFS('Sales Data'!$K$2:$K$201,'Sales Data'!$C$2:$C$201,$A7,'Sales Data'!$F$2:$F$201,B$3) -> 80276.556 | C7: =SUMIFS('Sales Data'!$K$2:$K$201,'Sales Data'!$C$2:$C$201,$A7,'Sales Data'!$F$2:$F$201,C$3) -> 42056.577 | D7: =SUMIFS('Sales Data'!$K$2:$K$201,'Sales Data'!$C$2:$C$201,$A7,'Sales Data'!$F$2:$F$201,D$3) -> 1079.507 | E7: =SUM(B7:D7) -> 123412.64
A8: Central | B8: =SUMIFS('Sales Data'!$K$2:$K$201,'Sales Data'!$C$2:$C$201,$A8,'Sales Data'!$F$2:$F$201,B$3) -> 90728.641 | C8: =SUMIFS('Sales Data'!$K$2:$K$201,'Sales Data'!$C$2:$C$201,$A8,'Sales Data'!$F$2:$F$201,C$3) -> 46729.823 | D8: =SUMIFS('Sales Data'!$K$2:$K$201,'Sales Data'!$C$2:$C$201,$A8,'Sales Data'!$F$2:$F$201,D$3) -> 2224.516 | E8: =SUM(B8:D8) -> 139682.98
A9: Total | B9: =SUM(B4:B8) -> 395179.35 | C9: =SUM(C4:C8) -> 273020.92 | D9: =SUM(D4:D8) -> 8203.4555 | E9: =SUM(E4:E8) -> 676403.73
A12: Salesperson | B12: Total Revenue
A13: Ali Raza | B13: =SUMIF('Sales Data'!$D$2:$D$201,A13,'Sales Data'!$K$2:$K$201) -> 40809.063
A14: Sana Khan | B14: =SUMIF('Sales Data'!$D$2:$D$201,A14,'Sales Data'!$K$2:$K$201) -> 140812.01
A15: Bilal Ahmed | B15: =SUMIF('Sales Data'!$D$2:$D$201,A15,'Sales Data'!$K$2:$K$201) -> 85459.081
A16: Ayesha Malik | B16: =SUMIF('Sales Data'!$D$2:$D$201,A16,'Sales Data'!$K$2:$K$201) -> 69110.905
A17: Usman Tariq | B17: =SUMIF('Sales Data'!$D$2:$D$201,A17,'Sales Data'!$K$2:$K$201) -> 64964.628
A18: Hina Farooq | B18: =SUMIF('Sales Data'!$D$2:$D$201,A18,'Sales Data'!$K$2:$K$201) -> 59606.12
A19: Zainab Iqbal | B19: =SUMIF('Sales Data'!$D$2:$D$201,A19,'Sales Data'!$K$2:$K$201) -> 124203.34
A20: Hamza Sheikh | B20: =SUMIF('Sales Data'!$D$2:$D$201,A20,'Sales Data'!$K$2:$K$201) -> 91438.574
A23: Month | B23: Total Revenue
A24: Jan | B24: =SUMPRODUCT((MONTH('Sales Data'!$B$2:$B$201)=1)*'Sales Data'!$K$2:$K$201) -> 43511.111
A25: Feb | B25: =SUMPRODUCT((MONTH('Sales Data'!$B$2:$B$201)=2)*'Sales Data'!$K$2:$K$201) -> 90983.572
A26: Mar | B26: =SUMPRODUCT((MONTH('Sales Data'!$B$2:$B$201)=3)*'Sales Data'!$K$2:$K$201) -> 93264.44
A27: Apr | B27: =SUMPRODUCT((MONTH('Sales Data'!$B$2:$B$201)=4)*'Sales Data'!$K$2:$K$201) -> 31611.668
A28: May | B28: =SUMPRODUCT((MONTH('Sales Data'!$B$2:$B$201)=5)*'Sales Data'!$K$2:$K$201) -> 25301.302
A29: Jun | B29: =SUMPRODUCT((MONTH('Sales Data'!$B$2:$B$201)=6)*'Sales Data'!$K$2:$K$201) -> 80923.23
A30: Jul | B30: =SUMPRODUCT((MONTH('Sales Data'!$B$2:$B$201)=7)*'Sales Data'!$K$2:$K$201) -> 56865.088
A31: Aug | B31: =SUMPRODUCT((MONTH('Sales Data'!$B$2:$B$201)=8)*'Sales Data'!$K$2:$K$201) -> 61804.55
A32: Sep | B32: =SUMPRODUCT((MONTH('Sales Data'!$B$2:$B$201)=9)*'Sales Data'!$K$2:$K$201) -> 16237.648
A33: Oct | B33: =SUMPRODUCT((MONTH('Sales Data'!$B$2:$B$201)=10)*'Sales Data'!$K$2:$K$201) -> 61012.554
A34: Nov | B34: =SUMPRODUCT((MONTH('Sales Data'!$B$2:$B$201)=11)*'Sales Data'!$K$2:$K$201) -> 67488.729
A35: Dec | B35: =SUMPRODUCT((MONTH('Sales Data'!$B$2:$B$201)=12)*'Sales Data'!$K$2:$K$201) -> 47399.832
A38: Category | B38: Total Revenue
A39: Electronics | B39: =SUMIF('Sales Data'!$F$2:$F$201,A39,'Sales Data'!$K$2:$K$201) -> 395179.35
A40: Furniture | B40: =SUMIF('Sales Data'!$F$2:$F$201,A40,'Sales Data'!$K$2:$K$201) -> 273020.92
A41: Stationery | B41: =SUMIF('Sales Data'!$F$2:$F$201,A41,'Sales Data'!$K$2:$K$201) -> 8203.4555
